Workbook

Sheet AVALUO
A1: ESPECIE | B1: TIPO | C1: ABARCADURA | D1: ALTURA | E1: VALOR al 40% | F1: Valor al 60% | G1: Valor al 70% | H1: valor al 100%
A2: ACACIA | B2: Segunda | C2: 106 | D2: 11.3 | E2: 184200 | F2: 276300 | G2: 322350 | H2: 460500
A3: POLVILLO | B3: Primera | C3: 116 | D3: 20 | E3: 669920 | F3: 1004880 | G3: 1172360 | H3: 1674800
A4: POLVILLO | B4: Primera | C4: 178 | D4: 17.8 | E4: 1366760 | F4: 2050140 | G4: 2391830 | H4: 3416900
A5: ACACIA | B5: Segunda | C5: 136 | D5: 20 | E5: 524640 | F5: 786960 | G5: 918120 | H5: 1311600
A6: ACACIA | B6: Segunda | C6: 151 | D6: 19.4 | E6: 649960 | F6: 974940 | G6: 1137430 | H6: 1624900
A7: ACACIA | B7: Segunda | C7: 156 | D7: 20 | E7: 788520 | F7: 1182780 | G7: 1379910 | H7: 1971300
A8: ACACIA | B8: Segunda | C8: 146 | D8: 17.6 | E8: 584000 | F8: 876000 | G8: 1022000 | H8: 1460000
A9: ACACIA | B9: Segunda | C9: 154 | D9: 18.9 | E9: 649960 | F9: 974940 | G9: 1137430 | H9: 1624900
A10: TOTAL | E10: =+SUM(E2:E9) -> 5417960 | F10: =+SUM(F2:F9) -> 8126940 | G10: =+SUM(G2:G9) -> 9481430 | H10: =+SUM(H2:H9) -> 13544900
A15: INDICE VALOR | B15: =+E1 -> VALOR al 40% | C15: =+F1 -> Valor al 60% | D15: =+G1 -> Valor al 70% | E15: =+H1 -> valor al 100%
A16: VALOR BASE IPC 2018 | B16: =+E10 -> 5417960 | C16: =+F10 -> 8126940 | D16: =+G10 -> 9481430 | E16: =+H10 -> 13544900
A17: VALOR IPC 2025 | B17: 8252000 | C17: 12379000 | D17: 14438000 | E17: 20628000

Sheet ESPECIES
A1: NOMBRE | B1: TIPO | D1: ESPECIES POR CATEGORIA
A2: Abarco | B2: Selección | D2: ESPECIE | E2: TIPO | F2: ABARCADURA CM | G2: ALTURA COMERCIAL MTS (RESTAR ALTURA TOTAL) | H2: VALOR UNITARIO 40% | I2: Valor al 60% | J2: Valor al 70% | K2: valor al 100%
A3: Acacia | B3: Segunda | D3: Acacia | E3: =VLOOKUP(D3,A:B,2,FALSE) -> Segunda | F3: 154 | G3: 18.9 | H3: =IF(E3="Primera",'PRIMERA_O&M'!$N$11,IF(E3="Segunda",'SEGUNDA_O&M'!$M$11,IF(E3="Tercera",'TERCERA_O&M'!$M$11,IF(E3="Selección","Pasar a tabla de Especies por selección")))) -> 649960 | I3: =(H3*60)/40 -> 974940 | J3: =(H3*70)/40 -> 1137430 | K3: =(H3*100)/40 -> 1624900
A4: Acacia Forrajera | B4: Tercera
A5: Acacia japonesa | B5: Segunda | D5: ESPECIES POR SELECCIÓN
A6: Aceite maría | B6: Primera | D6: ESPECIE | E6: TIPO | F6: ABARCADURA CM | G6: ALTURA COMERCIAL MTS (RESTAR ALTURA TOTAL) | H6: VALOR UNITARIO
A7: Aceite yumbe | B7: Selección | D7: =IF(E3="Selección",D3,"N/A") -> N/A | E7: Primera | F7: 140 | G7: 5.1 | H7: =IF(D7="N/A","N/A",(IF(E7="Primera",'PRIMERA_O&M'!$N$18,IF(E7="Segunda",'SEGUNDA_O&M'!$M$18,IF(E7="Tercera",'TERCERA_O&M'!$M$18))))) -> N/A
A8: Aceituno | B8: Segunda
A9: Acumico | B9: Tercera | D9: ESPECIE | E9: CANTIDAD | F9: ABARCADURA CM | G9: ALTURA COMERCIAL MTS (RESTAR ALTURA TOTAL) | H9: VALOR UNITARIO | I9: Total
A10: Acurruco | B10: Tercera | I10: =H10*E10 -> 0
A11: Aguacate | B11: Primera
A12: Aguacatillo | B12: Segunda
A13: Aguanoso | B13: Segunda
A14: Aguarrás | B14: Primera
A15: Ají de monte | B15: Tercera
A16: Ají sabana | B16: Tercera
A17: Ajicillo | B17: Segunda
A18: Ajujuay | B18: Segunda
A19: Alambre | B19: Tercera
A20: Albizia | B20: Primera
A21: Algarrobillo | B21: Primera
A22: Algarrobo | B22: Primera
... A26: Arayá | B26: Tercera
A27: Aro | B27: Segunda | I27: =H27*E27 -> 0
A28: Arrayán | B28: Segunda | I28: =H28*E28 -> 0
A29: Asauco | B29: Tercera
A30: Azulito | B30: Tercera
A31: Balaustre | B31: Segunda
A32: Balsamo macho | B32: Primera | I32: =H32*E32 -> 0
A33: Balsillo | B33: Primera | I33: =H33*E33 -> 0
A34: Balso | B34: segunda
A35: Baranoa | B35: Tercera
A36: Barbasco | B36: Segunda
A37: Bolombolo | B37: Tercera
A38: Búcaró | B38: Segunda
A39: Café | B39: Segunda
A40: Cafilo | B40: Tercera
A41: Caimito | B41: Tercera
A42: Caoba | B42: Primera
A43: Calambuco | B43: Segunda | I43: =H43*E43 -> 0
...

Sheet PRIMERA_O&M
B1: MADERA FINA O DE PRIMERA
B2: CAP en mts
A3: DAP | B3: 0.15 | C3: 0.2 | D3: 0.25 | E3: 0.3 | F3: 0.35 | G3: 0.4 | H3: 0.45 | I3: 0.5 | J3: 0.55 | K3: 0.6 | L3: Diametro en metros
A4: CAP | B4: 0.45 | C4: 0.6 | D4: 0.8 | E4: 1 | F4: 1.15 | G4: 1.3 | H4: 1.4 | I4: 1.55 | J4: 1.7 | K4: 1.85 | L4: Perimetro en metros
A5: ALTURA COMERCIAL (M)
A6: 1 | M6: ESPECIES POR CATEGORIA
A7: 2 | D7: 22360 | N7: CAP USURIO | O7: ALTURA
A8: 3 | C8: 17920 | D8: 33720 | E8: 51240 | M8: DATOS | N8: ='LISTAS Y RANGOS'!J3 -> 1.55 | O8: ='LISTAS Y RANGOS'!J6 -> 20
A9: 4 | C9: 26000 | D9: 45120 | E9: 68480 | F9: 96120 | M9: POSICION | N9: =MATCH(N8,$B$4:$K$4,0) -> 8 | O9: =MATCH(O8,$A$6:$A$20,0) -> 15
A10: 5 | C10: 32560 | D10: 56480 | E10: 85680 | F10: 120200 | G10: 160040
A11: 6 | B11: 17720 | C11: 39200 | D11: 66840 | E11: 100640 | F11: 140560 | G11: 186600 | H11: 238840 | M11: Valor unitario | N11: =INDEX(B6:K20,O9,N9) -> 1052360
A12: 7 | B12: 23560 | C12: 49560 | D12: 83040 | E12: 123920 | F12: 172240 | G12: 228040 | H12: 291240 | I12: 361880
A13: 8 | B13: 28320 | C13: 58080 | D13: 96320 | E13: 143040 | F13: 198280 | G13: 262000 | H13: 334240 | I13: 415000 | J13: 504200 | M13: ESPECIES POR SELECCIÓN
A14: 9 | B14: 33120 | C14: 66560 | D14: 109600 | E14: 162160 | F14: 224320 | G14: 296000 | H14: 377280 | I14: 468080 | J14: 568480 | K14: 678440 | N14: CAP USURIO | O14: ALTURA
A15: 10 | B15: 37880 | C15: 74960 | D15: 122880 | E15: 181280 | F15: 250320 | G15: 330000 | H15: 420280 | I15: 521200 | J15: 632760 | K15: 754920 | M15: DATOS | N15: ='LISTAS Y RANGOS'!J11 -> 1.4 | O15: ='LISTAS Y RANGOS'!J14 -> 6
A16: 12 | B16: 45360 | C16: 88360 | D16: 143640 | E16: 211200 | F16: 291040 | G16: 383160 | H16: 487560 | I16: 604280 | J16: 733240 | K16: 874520 | M16: POSICION | N16: =MATCH(N15,$B$4:$K$4,0) -> 7 | O16: =MATCH(O15,$A$6:$A$20,0) -> 6
A17: 14 | B17: 57000 | C17: 109040 | D17: 175960 | E17: 257760 | F17: 354440 | G17: 465960 | H17: 592400 | I17: 733680 | J17: 889800 | K17: 1060840
A18: 16 | B18: 66560 | C18: 126040 | D18: 202520 | E18: 296000 | F18: 406480 | G18: 533960 | H18: 678440 | I18: 839880 | J18: 1018360 | K18: 1213800 | M18: Valor unitario | N18: =INDEX(B6:K20,O16,N16) -> 238840
A19: 18 | B19: 76120 | C19: 143040 | D19: 229080 | E19: 334240 | F19: 458520 | G19: 601960 | H19: 764480 | I19: 946120 | J19: 1146880 | K19: 1366760
A20: 20 | B20: 85680 | C20: 160040 | D20: 255640 | E20: 372480 | F20: 510600 | G20: 669920 | H20: 850520 | I20: 1052360 | J20: 1275400 | K20: 1519720

Sheet SEGUNDA_O&M
B1: MADERA REGULAR O DE SEGUNDA
B2: DAP
A3: DAP | B3: 0.2 | C3: 0.25 | D3: 0.3 | E3: 0.35 | F3: 0.4 | G3: 0.45 | H3: 0.5 | I3: 0.55 | J3: 0.6 | K3: Diametro en metros
A4: CAP | B4: 0.6 | C4: 0.8 | D4: 1 | E4: 1.15 | F4: 1.3 | G4: 1.4 | H4: 1.55 | I4: 1.7 | J4: 1.85 | K4: Perimetro en metros
A5: ALTURA COMERCIAL (M)
A6: 1
A7: 2 | M7: CAP USURIO | N7: ALTURA
A8: 3 | C8: 18800 | D8: 29680 | L8: DATOS | M8: ='LISTAS Y RANGOS'!J3 -> 1.55 | N8: ='LISTAS Y RANGOS'!J6 -> 20
A9: 4 | C9: 25120 | D9: 39640 | E9: 56760 | L9: POSICION | M9: =MATCH(M8,$B$4:$K$4,0) -> 7 | N9: =MATCH(N8,$A$6:$A$20,0) -> 15
A10: 5 | B10: 16640 | C10: 31480 | D10: 49600 | E10: 71040 | F10: 95800
A11: 6 | B11: 21920 | C11: 39720 | D11: 61480 | E11: 87240 | F11: 116920 | G11: 150560 | L11: Valor unitario | M11: =INDEX($B$6:$J$20,N9,M9) -> 649960
A12: 7 | B12: 27200 | C12: 47960 | D12: 73360 | E12: 103400 | F12: 138040 | G12: 177280 | H12: 221160
A13: 8 | B13: 32480 | C13: 56200 | D13: 85240 | E13: 119400 | F13: 159120 | G13: 204000 | H13: 254120 | I13: 309560
A14: 9 | B14: 37760 | C14: 64480 | D14: 97120 | E14: 135720 | F14: 180240 | G14: 230720 | H14: 287120 | I14: 349480 | J14: 417760 | M14: CAP USURIO | N14: ALTURA
A15: 10 | B15: 43000 | C15: 72720 | D15: 109000 | E15: 151880 | F15: 201360 | G15: 257440 | H15: 320120 | I15: 389360 | J15: 465240 | L15: DATOS | M15: ='LISTAS Y RANGOS'!J11 -> 1.4 | N15: ='LISTAS Y RANGOS'!J14 -> 6
A16: 12 | B16: 53560 | C16: 89200 | D16: 132760 | E16: 184200 | F16: 243560 | G16: 310880 | H16: 386080 | I16: 469200 | J16: 560240 | L16: POSICION | M16: =MATCH(M15,$B$4:$K$4,0) -> 6 | N16: =MATCH(N15,$A$6:$A$20,0) -> 6
A17: 14 | B17: 64120 | C17: 105680 | D17: 156480 | E17: 216520 | F17: 285800 | G17: 364320 | H17: 452040 | I17: 549040 | J17: 655240
A18: 16 | B18: 74680 | C18: 122200 | D18: 180240 | E18: 248840 | F18: 328040 | G18: 417760 | H18: 518040 | I18: 628880 | J18: 750240 | L18: Valor unitario | M18: =INDEX($B$6:$J$20,N16,M16) -> 150560
A19: 18 | B19: 85240 | C19: 138600 | D19: 204000 | E19: 281200 | F19: 370240 | G19: 471200 | H19: 584000 | I19: 708680 | J19: 845240
A20: 20 | B20: 95800 | C20: 155160 | D20: 227760 | E20: 313520 | F20: 412480 | G20: 524640 | H20: 649960 | I20: 788520 | J20: 940240

Sheet TERCERA_O&M
B1: MADERA ORDINARIA O DE TERCERA
B2: DAP
B3: 0.2 | C3: 0.25 | D3: 0.3 | E3: 0.35 | F3: 0.4 | G3: 0.45 | H3: 0.5 | I3: 0.55 | J3: 0.6 | K3: Diametro en metros
B4: 0.6 | C4: 0.8 | D4: 1 | E4: 1.15 | F4: 1.3 | G4: 1.4 | H4: 1.55 | I4: 1.7 | J4: 1.85 | K4: Perimetro en metros
A5: ALTURA COMERCIAL (M)
A6: 1
A7: 2 | M7: CAP USURIO | N7: ALTURA
A8: 3 | D8: 19440 | L8: DATOS | M8: ='LISTAS Y RANGOS'!J3 -> 1.55 | N8: ='LISTAS Y RANGOS'!J6 -> 20
A9: 4 | D9: 26040 | E9: 38320 | L9: POSICION | M9: =MATCH(M8,$B$4:$K$4,0) -> 7 | N9: =MATCH(N8,$A$6:$A$20,0) -> 15
A10: 5 | C10: 19640 | D10: 32600 | E10: 47920 | F10: 65600
A11: 6 | C11: 25560 | D11: 41080 | E11: 59480 | F11: 80680 | G11: 104720 | L11: Valor unitario | M11: =INDEX($B$6:$J$20,N9,M9) -> 461440
A12: 7 | B12: 16600 | C12: 31440 | D12: 49560 | E12: 71000 | F12: 95760 | G12: 123800 | H12: 155120
A13: 8 | B13: 20360 | C13: 37320 | D13: 58040 | E13: 82560 | F13: 110840 | G13: 142880 | H13: 178680 | I13: 218280
A14: 9 | B14: 26960 | C14: 47640 | D14: 72920 | E14: 102760 | F14: 137240 | G14: 176280 | H14: 219920 | I14: 268160 | J14: 321000 | M14: CAP USURIO | N14: ALTURA
A15: 10 | B15: 27880 | C15: 49120 | D15: 75040 | E15: 105640 | F15: 141000 | G15: 181040 | H15: 225800 | I15: 275280 | J15: 329480 | L15: DATOS | M15: ='LISTAS Y RANGOS'!J11 -> 1.4 | N15: ='LISTAS Y RANGOS'!J14 -> 6
A16: 12 | B16: 35440 | C16: 60880 | D16: 92000 | E16: 128760 | F16: 171160 | G16: 218040 | H16: 272960 | I16: 332320 | J16: 397360 | L16: POSICION | M16: =MATCH(M15,$B$4:$K$4,0) -> 6 | N16: =MATCH(N15,$A$6:$A$20,0) -> 6
A17: 14 | B17: 42960 | C17: 72680 | D17: 108960 | E17: 151840 | F17: 201320 | G17: 257400 | H17: 320080 | I17: 389320 | J17: 465200
A18: 16 | B18: 50520 | C18: 84440 | D18: 125920 | E18: 175040 | F18: 231480 | G18: 295560 | H18: 367200 | I18: 446360 | J18: 533080 | L18: Valor unitario | M18: =INDEX($B$6:$J$20,N16,M16) -> 104720
A19: 18 | B19: 58040 | C19: 96240 | D19: 142880 | E19: 198000 | F19: 261640 | G19: 333720 | H19: 414320 | I19: 503360 | J19: 600920
A20: 20 | B20: 65600 | C20: 108000 | D20: 159840 | E20: 221120 | F20: 291800 | G20: 371920 | H20: 461440 | I20: 560400 | J20: 668800

Sheet LISTAS Y RANGOS
D1: PRIMERA | E1: SEGUNDA | F1: TERCERA
A2: LISTA | C2: POSICIÓN | D2: RANGO CAP | E2: RANGO CAP | F2: RANGO CAP | G2: RANGO ALTURA | I2: CAP USUARIO | J2: CAP AJUSTADO
A3: Primera | C3: 1 | D3: 0.45 | E3: 0.6 | F3: 0.6 | G3: 1 | I3: =ESPECIES!F3/100 -> 1.54 | J3: {=IF(I3>MAX(D3:F12),F12,(IF(ESPECIES!E3="Primera",MIN(IF(D3:D12>=I3,D3:D12)),IF(ESPECIES!E3="Segunda",MIN(IF(E3:E12>=I3,E3:E12)),IF(ESPECIES!E3="Tercera",MIN(IF(F3:F12>=I3,F3:F12)))))))} -> 1.55
A4: Segunda | C4: 2 | D4: 0.6 | E4: 0.6 | F4: 0.6 | G4: 2
A5: Tercera | C5: 3 | D5: 0.8 | E5: 0.8 | F5: 0.8 | G5: 3 | I5: ALT USUARIO | J5: ALT AJUSTADO
C6: 4 | D6: 1 | E6: 1 | F6: 1 | G6: 4 | I6: =ESPECIES!G3 -> 18.9 | J6: {=MIN(IF(G3:G17>=I6,G3:G17))} -> 20
C7: 5 | D7: 1.15 | E7: 1.15 | F7: 1.15 | G7: 5
C8: 6 | D8: 1.3 | E8: 1.3 | F8: 1.3 | G8: 6
C9: 7 | D9: 1.4 | E9: 1.4 | F9: 1.4 | G9: 7
C10: 8 | D10: 1.55 | E10: 1.55 | F10: 1.55 | G10: 8 | I10: CAP USUARIO | J10: CAP AJUSTADO
C11: 9 | D11: 1.7 | E11: 1.7 | F11: 1.7 | G11: 9 | I11: =ESPECIES!F7/100 -> 1.4 | J11: {=IF(I11>MAX(D3:F12),F12,(IF(ESPECIES!E7="Primera",MIN(IF(D3:D12>=I11,D3:D12)),IF(ESPECIES!E7="Segunda",MIN(IF(E3:E12>=I11,E3:E12)),IF(ESPECIES!E7="Tercera",MIN(IF(F3:F12>=I11,F3:F12)))))))} -> 1.4
C12: 10 | D12: 1.85 | E12: 1.85 | F12: 1.85 | G12: 10
C13: 11 | G13: 12 | I13: ALT USUARIO | J13: ALT AJUSTADO
C14: 12 | G14: 14 | I14: =ESPECIES!G7 -> 5.1 | J14: {=MIN(IF(G3:G17>=I14,G3:G17))} -> 6
C15: 13 | G15: 16
C16: 14 | G16: 18
C17: 15 | G17: 20
